Workbook

Sheet Raw Data
A1: Transaction_ID | B1: Date | C1: Customer_ID | D1: Customer_Name | E1: Product_ID | F1: Product_Name | G1: Category | H1: Quantity | I1: Unit_Price | J1: Payment_Method | K1: Region | L1: Customer_Segment | M1: Customer_Since | N1: Total_Amount | O1: Month_Start | P1: Month_End | Q1: Tenure_Yrs | R1: Days_Since_Purchase | S1: Name_Count | T1: Purchase_Type | U1: Filter_Seq
A2: TRX0155 | B2: 45393 | C2: CUST023 | D2: Paul Baker | E2: P009 | F2: Monitor | G2: Electronics | H2: 3 | I2: 249.99 | J2: Cash | K2: Central | L2: Basic | M2: 44425 | N2: 749.97 | O2: =EOMONTH(B2,-1)+1 -> 45383 | P2: =EOMONTH(B2,0) -> 45412 | Q2: =IFERROR(DATEDIF(M2,B2,"Y"),0) -> 2 | R2: =TODAY()-B2 -> 931 | S2: =COUNTIF($D$2:$D$251,D2) -> 8 | T2: =IF(COUNTIF($D$2:D2,D2)=1,"First","Repeat") -> First | U2: =IF(AND($K2=DateTime_Filter!$C$21,$N2>=DateTime_Filter!$C$22),MAX(U$1:U1)+1,"")
A3: TRX0023 | B3: 45396 | C3: CUST013 | D3: Joseph Jackson | E3: P009 | F3: Monitor | G3: Electronics | H3: 3 | I3: 249.99 | J3: Credit Card | K3: Central | L3: Premium | M3: 44575 | N3: 749.97 | O3: =EOMONTH(B3,-1)+1 -> 45383 | P3: =EOMONTH(B3,0) -> 45412 | Q3: =IFERROR(DATEDIF(M3,B3,"Y"),0) -> 2 | R3: =TODAY()-B3 -> 928 | S3: =COUNTIF($D$2:$D$251,D3) -> 5 | T3: =IF(COUNTIF($D$2:D3,D3)=1,"First","Repeat") -> First | U3: =IF(AND($K3=DateTime_Filter!$C$21,$N3>=DateTime_Filter!$C$22),MAX(U$1:U2)+1,"")
A4: TRX0139 | B4: 45399 | C4: CUST021 | D4: Kevin Scott | E4: P005 | F4: Blender | G4: Appliances | H4: 3 | I4: 59.99 | J4: PayPal | K4: South | L4: Standard | M4: 45262 | N4: 179.97 | O4: =EOMONTH(B4,-1)+1 -> 45383 | P4: =EOMONTH(B4,0) -> 45412 | Q4: =IFERROR(DATEDIF(M4,B4,"Y"),0) -> 0 | R4: =TODAY()-B4 -> 925 | S4: =COUNTIF($D$2:$D$251,D4) -> 6 | T4: =IF(COUNTIF($D$2:D4,D4)=1,"First","Repeat") -> First | U4: =IF(AND($K4=DateTime_Filter!$C$21,$N4>=DateTime_Filter!$C$22),MAX(U$1:U3)+1,"")
A5: TRX0043 | B5: 45400 | C5: CUST046 | D5: Kathleen Bennett | E5: P005 | F5: Blender | G5: Appliances | H5: 3 | I5: 59.99 | J5: Cash | K5: North | L5: Premium | M5: 45114 | N5: 179.97 | O5: =EOMONTH(B5,-1)+1 -> 45383 | P5: =EOMONTH(B5,0) -> 45412 | Q5: =IFERROR(DATEDIF(M5,B5,"Y"),0) -> 0 | R5: =TODAY()-B5 -> 924 | S5: =COUNTIF($D$2:$D$251,D5) -> 6 | T5: =IF(COUNTIF($D$2:D5,D5)=1,"First","Repeat") -> First | U5: =IF(AND($K5=DateTime_Filter!$C$21,$N5>=DateTime_Filter!$C$22),MAX(U$1:U4)+1,"")
A6: TRX0212 | B6: 45400 | C6: CUST003 | D6: Michael Brown | E6: P008 | F6: Bookshelf | G6: Furniture | H6: 5 | I6: 149.99 | J6: Credit Card | K6: North | L6: Premium | M6: 45295 | N6: 749.95 | O6: =EOMONTH(B6,-1)+1 -> 45383 | P6: =EOMONTH(B6,0) -> 45412 | Q6: =IFERROR(DATEDIF(M6,B6,"Y"),0) -> 0 | R6: =TODAY()-B6 -> 924 | S6: =COUNTIF($D$2:$D$251,D6) -> 9 | T6: =IF(COUNTIF($D$2:D6,D6)=1,"First","Repeat") -> First | U6: =IF(AND($K6=DateTime_Filter!$C$21,$N6>=DateTime_Filter!$C$22),MAX(U$1:U5)+1,"")
A7: TRX0092 | B7: 45403 | C7: CUST024 | D7: Dorothy Nelson | E7: P005 | F7: Blender | G7: Appliances | H7: 2 | I7: 59.99 | J7: Cash | K7: West | L7: Standard | M7: 44746 | N7: 119.98 | O7: =EOMONTH(B7,-1)+1 -> 45383 | P7: =EOMONTH(B7,0) -> 45412 | Q7: =IFERROR(DATEDIF(M7,B7,"Y"),0) -> 1 | R7: =TODAY()-B7 -> 921 | S7: =COUNTIF($D$2:$D$251,D7) -> 6 | T7: =IF(COUNTIF($D$2:D7,D7)=1,"First","Repeat") -> First | U7: =IF(AND($K7=DateTime_Filter!$C$21,$N7>=DateTime_Filter!$C$22),MAX(U$1:U6)+1,"")
A8: TRX0193 | B8: 45403 | C8: CUST024 | D8: Dorothy Nelson | E8: P003 | F8: Headphones | G8: Electronics | H8: 5 | I8: 149.99 | J8: Credit Card | K8: Central | L8: Standard | M8: 44418 | N8: 749.95 | O8: =EOMONTH(B8,-1)+1 -> 45383 | P8: =EOMONTH(B8,0) -> 45412 | Q8: =IFERROR(DATEDIF(M8,B8,"Y"),0) -> 2 | R8: =TODAY()-B8 -> 921 | S8: =COUNTIF($D$2:$D$251,D8) -> 6 | T8: =IF(COUNTIF($D$2:D8,D8)=1,"First","Repeat") -> Repeat | U8: =IF(AND($K8=DateTime_Filter!$C$21,$N8>=DateTime_Filter!$C$22),MAX(U$1:U7)+1,"")
A9: TRX0240 | B9: 45403 | C9: CUST017 | D9: Charles Allen | E9: P005 | F9: Blender | G9: Appliances | H9: 3 | I9: 59.99 | J9: Debit Card | K9: South | L9: Basic | M9: 45007 | N9: 179.97 | O9: =EOMONTH(B9,-1)+1 -> 45383 | P9: =EOMONTH(B9,0) -> 45412 | Q9: =IFERROR(DATEDIF(M9,B9,"Y"),0) -> 1 | R9: =TODAY()-B9 -> 921 | S9: =COUNTIF($D$2:$D$251,D9) -> 9 | T9: =IF(COUNTIF($D$2:D9,D9)=1,"First","Repeat") -> First | U9: =IF(AND($K9=DateTime_Filter!$C$21,$N9>=DateTime_Filter!$C$22),MAX(U$1:U8)+1,"")
A10: TRX0135 | B10: 45405 | C10: CUST009 | D10: Robert Thomas | E10: P001 | F10: Laptop | G10: Electronics | H10: 3 | I10: 899.99 | J10: PayPal | K10: East | L10: Standard | M10: 45299 | N10: 2699.97 | O10: =EOMONTH(B10,-1)+1 -> 45383 | P10: =EOMONTH(B10,0) -> 45412 | Q10: =IFERROR(DATEDIF(M10,B10,"Y"),0) -> 0 | R10: =TODAY()-B10 -> 919 | S10: =COUNTIF($D$2:$D$251,D10) -> 5 | T10: =IF(COUNTIF($D$2:D10,D10)=1,"First","Repeat") -> First | U10: =IF(AND($K10=DateTime_Filter!$C$21,$N10>=DateTime_Filter!$C$22),MAX(U$1:U9)+1,"")
A11: TRX0138 | B11: 45408 | C11: CUST022 | D11: Susan Green | E11: P008 | F11: Bookshelf | G11: Furniture | H11: 1 | I11: 149.99 | J11: Credit Card | K11: West | L11: Standard | M11: 45103 | N11: 149.99 | O11: =EOMONTH(B11,-1)+1 -> 45383 | P11: =EOMONTH(B11,0) -> 45412 | Q11: =IFERROR(DATEDIF(M11,B11,"Y"),0) -> 0 | R11: =TODAY()-B11 -> 916 | S11: =COUNTIF($D$2:$D$251,D11) -> 4 | T11: =IF(COUNTIF($D$2:D11,D11)=1,"First","Repeat") -> First | U11: =IF(AND($K11=DateTime_Filter!$C$21,$N11>=DateTime_Filter!$C$22),MAX(U$1:U10)+1,"")
A12: TRX0185 | B12: 45408 | C12: CUST026 | D12: Karen Hill | E12: P005 | F12: Blender | G12: Appliances | H12: 3 | I12: 59.99 | J12: Cash | K12: West | L12: Premium | M12: 45207 | N12: 179.97 | O12: =EOMONTH(B12,-1)+1 -> 45383 | P12: =EOMONTH(B12,0) -> 45412 | Q12: =IFERROR(DATEDIF(M12,B12,"Y"),0) -> 0 | R12: =TODAY()-B12 -> 916 | S12: =COUNTIF($D$2:$D$251,D12) -> 8 | T12: =IF(COUNTIF($D$2:D12,D12)=1,"First","Repeat") -> First | U12: =IF(AND($K12=DateTime_Filter!$C$21,$N12>=DateTime_Filter!$C$22),MAX(U$1:U11)+1,"")
A13: TRX0209 | B13: 45408 | C13: CUST046 | D13: Kathleen Bennett | E13: P008 | F13: Bookshelf | G13: Furniture | H13: 5 | I13: 149.99 | J13: Debit Card | K13: North | L13: Basic | M13: 44830 | N13: 749.95 | O13: =EOMONTH(B13,-1)+1 -> 45383 | P13: =EOMONTH(B13,0) -> 45412 | Q13: =IFERROR(DATEDIF(M13,B13,"Y"),0) -> 1 | R13: =TODAY()-B13 -> 916 | S13: =COUNTIF($D$2:$D$251,D13) -> 6 | T13: =IF(COUNTIF($D$2:D13,D13)=1,"First","Repeat") -> Repeat | U13: =IF(AND($K13=DateTime_Filter!$C$21,$N13>=DateTime_Filter!$C$22),MAX(U$1:U12)+1,"")
... A251: TRX0120 | B251: 45758 | C251: CUST045 | D251: Douglas Watson | E251: P002 | F251: Smartphone | G251: Electronics | H251: 3 | I251: 699.99 | J251: PayPal | K251: North | L251: Basic | M251: 44909 | N251: 2099.97 | O251: =EOMONTH(B251,-1)+1 -> 45748 | P251: =EOMONTH(B251,0) -> 45777 | Q251: =IFERROR(DATEDIF(M251,B251,"Y"),0) -> 2 | R251: =TODAY()-B251 -> 566 | S251: =COUNTIF($D$2:$D$251,D251) -> 4 | T251: =IF(COUNTIF($D$2:D251,D251)=1,"First","Repeat") -> Repeat | U251: =IF(AND($K251=DateTime_Filter!$C$21,$N251>=DateTime_Filter!$C$22),MAX(U$1:U250)+1,"") -> 14

Sheet Analysis
A1: Analysis Sheet – Formula-based Summary Tables
A3: KPI Summary
A4: Total Revenue | B4: =SUM('Raw Data'!$N$2:$N$251) -> 229192.47
A5: Total Transactions | B5: =COUNTA('Raw Data'!$A$2:$A$251) -> 250
A6: Total Units Sold | B6: =SUM('Raw Data'!$H$2:$H$251) -> 753
A7: Average Order Value | B7: =B4/B5 -> 916.76988
A8: Unique Customers | B8: =SUMPRODUCT(1/COUNTIF('Raw Data'!$C$2:$C$251,'Raw Data'!$C$2:$C$251)) -> 50
A9: Avg Revenue per Customer | B9: =B4/B8 -> 4583.8494
A11: Sales by Region
A12: Region | B12: Revenue | C12: Orders | D12: Units | E12: % of Revenue | F12: Avg Order Value | G12: Performance Index (vs avg)
A13: Central | B13: =SUMIFS('Raw Data'!$N$2:$N$251,'Raw Data'!$K$2:$K$251,$A13) -> 41288.34 | C13: =COUNTIFS('Raw Data'!$K$2:$K$251,$A13) -> 54 | D13: =SUMIFS('Raw Data'!$H$2:$H$251,'Raw Data'!$K$2:$K$251,$A13) -> 166 | E13: =B13/$B$18 -> 0.18014702 | F13: =IFERROR(B13/C13,0) -> 764.59889 | G13: =B13/AVERAGE($B$13:$B$17) -> 0.90073509
A14: East | B14: =SUMIFS('Raw Data'!$N$2:$N$251,'Raw Data'!$K$2:$K$251,$A14) -> 59288.39 | C14: =COUNTIFS('Raw Data'!$K$2:$K$251,$A14) -> 48 | D14: =SUMIFS('Raw Data'!$H$2:$H$251,'Raw Data'!$K$2:$K$251,$A14) -> 161 | E14: =B14/$B$18 -> 0.25868385 | F14: =IFERROR(B14/C14,0) -> 1235.1748 | G14: =B14/AVERAGE($B$13:$B$17) -> 1.2934192
A15: North | B15: =SUMIFS('Raw Data'!$N$2:$N$251,'Raw Data'!$K$2:$K$251,$A15) -> 50808.31 | C15: =COUNTIFS('Raw Data'!$K$2:$K$251,$A15) -> 59 | D15: =SUMIFS('Raw Data'!$H$2:$H$251,'Raw Data'!$K$2:$K$251,$A15) -> 169 | E15: =B15/$B$18 -> 0.22168403 | F15: =IFERROR(B15/C15,0) -> 861.1578 | G15: =B15/AVERAGE($B$13:$B$17) -> 1.1084201
A16: South | B16: =SUMIFS('Raw Data'!$N$2:$N$251,'Raw Data'!$K$2:$K$251,$A16) -> 36398.75 | C16: =COUNTIFS('Raw Data'!$K$2:$K$251,$A16) -> 42 | D16: =SUMIFS('Raw Data'!$H$2:$H$251,'Raw Data'!$K$2:$K$251,$A16) -> 125 | E16: =B16/$B$18 -> 0.15881303 | F16: =IFERROR(B16/C16,0) -> 866.6369 | G16: =B16/AVERAGE($B$13:$B$17) -> 0.79406514
A17: West | B17: =SUMIFS('Raw Data'!$N$2:$N$251,'Raw Data'!$K$2:$K$251,$A17) -> 41408.68 | C17: =COUNTIFS('Raw Data'!$K$2:$K$251,$A17) -> 47 | D17: =SUMIFS('Raw Data'!$H$2:$H$251,'Raw Data'!$K$2:$K$251,$A17) -> 132 | E17: =B17/$B$18 -> 0.18067208 | F17: =IFERROR(B17/C17,0) -> 881.03574 | G17: =B17/AVERAGE($B$13:$B$17) -> 0.90336039
A18: Total | B18: =SUM(B13:B17) -> 229192.47 | C18: =SUM(C13:C17) -> 250 | D18: =SUM(D13:D17) -> 753 | E18: =SUM(E13:E17) -> 1 | F18: =B18/C18 -> 916.76988
A20: Sales by Category
A21: Category | B21: Revenue | C21: Orders | D21: Units | E21: % of Revenue | F21: Avg Order Value
A22: Appliances | B22: =SUMIFS('Raw Data'!$N$2:$N$251,'Raw Data'!$G$2:$G$251,$A22) -> 8338.74 | C22: =COUNTIFS('Raw Data'!$G$2:$G$251,$A22) -> 43 | D22: =SUMIFS('Raw Data'!$H$2:$H$251,'Raw Data'!$G$2:$G$251,$A22) -> 126 | E22: =B22/$B$25 -> 0.036383132 | F22: =IFERROR(B22/C22,0) -> 193.92419
A23: Electronics | B23: =SUMIFS('Raw Data'!$N$2:$N$251,'Raw Data'!$G$2:$G$251,$A23) -> 171756.05 | C23: =COUNTIFS('Raw Data'!$G$2:$G$251,$A23) -> 131 | D23: =SUMIFS('Raw Data'!$H$2:$H$251,'Raw Data'!$G$2:$G$251,$A23) -> 395 | E23: =B23/$B$25 -> 0.74939657 | F23: =IFERROR(B23/C23,0) -> 1311.1149
A24: Furniture | B24: =SUMIFS('Raw Data'!$N$2:$N$251,'Raw Data'!$G$2:$G$251,$A24) -> 49097.68 | C24: =COUNTIFS('Raw Data'!$G$2:$G$251,$A24) -> 76 | D24: =SUMIFS('Raw Data'!$H$2:$H$251,'Raw Data'!$G$2:$G$251,$A24) -> 232 | E24: =B24/$B$25 -> 0.2142203 | F24: =IFERROR(B24/C24,0) -> 646.02211
A25: Total | B25: =SUM(B22:B24) -> 229192.47 | C25: =SUM(C22:C24) -> 250 | D25: =SUM(D22:D24) -> 753 | E25: =SUM(E22:E24) -> 1 | F25: =B25/C25 -> 916.76988
A27: Sales by Product
A28: Product_ID | B28: Product_Name | C28: Category | D28: Unit_Price | E28: Orders | F28: Units | G28: Revenue | H28: Rank (Units) | I28: Abbreviation
A29: P001 | B29: =INDEX('Raw Data'!$F$2:$F$251,MATCH(A29,'Raw Data'!$E$2:$E$251,0)) -> Laptop | C29: =INDEX('Raw Data'!$G$2:$G$251,MATCH(A29,'Raw Data'!$E$2:$E$251,0)) -> Electronics | D29: =INDEX('Raw Data'!$I$2:$I$251,MATCH(A29,'Raw Data'!$E$2:$E$251,0)) -> 899.99 | E29: =COUNTIFS('Raw Data'!$E$2:$E$251,A29) -> 24 | F29: =SUMIFS('Raw Data'!$H$2:$H$251,'Raw Data'!$E$2:$E$251,A29) -> 75 | G29: =SUMIFS('Raw Data'!$N$2:$N$251,'Raw Data'!$E$2:$E$251,A29) -> 67499.25 | H29: =RANK(F29,$F$29:$F$38)+COUNTIF($F$29:F29,F29)-1 -> 7 | I29: =UPPER(LEFT(C29,3))&"-"&UPPER(LEFT(B29,3))&"-"&RIGHT(A29,2) -> ELE-LAP-01
A30: P002 | B30: =INDEX('Raw Data'!$F$2:$F$251,MATCH(A30,'Raw Data'!$E$2:$E$251,0)) -> Smartphone | C30: =INDEX('Raw Data'!$G$2:$G$251,MATCH(A30,'Raw Data'!$E$2:$E$251,0)) -> Electronics | D30: =INDEX('Raw Data'!$I$2:$I$251,MATCH(A30,'Raw Data'!$E$2:$E$251,0)) -> 699.99 | E30: =COUNTIFS('Raw Data'!$E$2:$E$251,A30) -> 31 | F30: =SUMIFS('Raw Data'!$H$2:$H$251,'Raw Data'!$E$2:$E$251,A30) -> 96 | G30: =SUMIFS('Raw Data'!$N$2:$N$251,'Raw Data'!$E$2:$E$251,A30) -> 67199.04 | H30: =RANK(F30,$F$29:$F$38)+COUNTIF($F$29:F30,F30)-1 -> 2 | I30: =UPPER(LEFT(C30,3))&"-"&UPPER(LEFT(B30,3))&"-"&RIGHT(A30,2) -> ELE-SMA-02
A31: P003 | B31: =INDEX('Raw Data'!$F$2:$F$251,MATCH(A31,'Raw Data'!$E$2:$E$251,0)) -> Headphones | C31: =INDEX('Raw Data'!$G$2:$G$251,MATCH(A31,'Raw Data'!$E$2:$E$251,0)) -> Electronics | D31: =INDEX('Raw Data'!$I$2:$I$251,MATCH(A31,'Raw Data'!$E$2:$E$251,0)) -> 149.99 | E31: =COUNTIFS('Raw Data'!$E$2:$E$251,A31) -> 16 | F31: =SUMIFS('Raw Data'!$H$2:$H$251,'Raw Data'!$E$2:$E$251,A31) -> 47 | G31: =SUMIFS('Raw Data'!$N$2:$N$251,'Raw Data'!$E$2:$E$251,A31) -> 7049.53 | H31: =RANK(F31,$F$29:$F$38)+COUNTIF($F$29:F31,F31)-1 -> 9 | I31: =UPPER(LEFT(C31,3))&"-"&UPPER(LEFT(B31,3))&"-"&RIGHT(A31,2) -> ELE-HEA-03
A32: P004 | B32: =INDEX('Raw Data'!$F$2:$F$251,MATCH(A32,'Raw Data'!$E$2:$E$251,0)) -> Coffee Maker | C32: =INDEX('Raw Data'!$G$2:$G$251,MATCH(A32,'Raw Data'!$E$2:$E$251,0)) -> Appliances | D32: =INDEX('Raw Data'!$I$2:$I$251,MATCH(A32,'Raw Data'!$E$2:$E$251,0)) -> 79.99 | E32: =COUNTIFS('Raw Data'!$E$2:$E$251,A32) -> 14 | F32: =SUMIFS('Raw Data'!$H$2:$H$251,'Raw Data'!$E$2:$E$251,A32) -> 39 | G32: =SUMIFS('Raw Data'!$N$2:$N$251,'Raw Data'!$E$2:$E$251,A32) -> 3119.61 | H32: =RANK(F32,$F$29:$F$38)+COUNTIF($F$29:F32,F32)-1 -> 10 | I32: =UPPER(LEFT(C32,3))&"-"&UPPER(LEFT(B32,3))&"-"&RIGHT(A32,2) -> APP-COF-04
A33: P005 | B33: =INDEX('Raw Data'!$F$2:$F$251,MATCH(A33,'Raw Data'!$E$2:$E$251,0)) -> Blender | C33: =INDEX('Raw Data'!$G$2:$G$251,MATCH(A33,'Raw Data'!$E$2:$E$251,0)) -> Appliances | D33: =INDEX('Raw Data'!$I$2:$I$251,MATCH(A33,'Raw Data'!$E$2:$E$251,0)) -> 59.99 | E33: =COUNTIFS('Raw Data'!$E$2:$E$251,A33) -> 29 | F33: =SUMIFS('Raw Data'!$H$2:$H$251,'Raw Data'!$E$2:$E$251,A33) -> 87 | G33: =SUMIFS('Raw Data'!$N$2:$N$251,'Raw Data'!$E$2:$E$251,A33) -> 5219.13 | H33: =RANK(F33,$F$29:$F$38)+COUNTIF($F$29:F33,F33)-1 -> 5 | I33: =UPPER(LEFT(C33,3))&"-"&UPPER(LEFT(B33,3))&"-"&RIGHT(A33,2) -> APP-BLE-05
A34: P006 | B34: =INDEX('Raw Data'!$F$2:$F$251,MATCH(A34,'Raw Data'!$E$2:$E$251,0)) -> Office Chair | C34: =INDEX('Raw Data'!$G$2:$G$251,MATCH(A34,'Raw Data'!$E$2:$E$251,0)) -> Furniture | D34: =INDEX('Raw Data'!$I$2:$I$251,MATCH(A34,'Raw Data'!$E$2:$E$251,0)) -> 199.99 | E34: =COUNTIFS('Raw Data'!$E$2:$E$251,A34) -> 15 | F34: =SUMIFS('Raw Data'!$H$2:$H$251,'Raw Data'!$E$2:$E$251,A34) -> 52 | G34: =SUMIFS('Raw Data'!$N$2:$N$251,'Raw Data'!$E$2:$E$251,A34) -> 10399.48 | H34: =RANK(F34,$F$29:$F$38)+COUNTIF($F$29:F34,F34)-1 -> 8 | I34: =UPPER(LEFT(C34,3))&"-"&UPPER(LEFT(B34,3))&"-"&RIGHT(A34,2) -> FUR-OFF-06
A35: P007 | B35: =INDEX('Raw Data'!$F$2:$F$251,MATCH(A35,'Raw Data'!$E$2:$E$251,0)) -> Desk | C35: =INDEX('Raw Data'!$G$2:$G$251,MATCH(A35,'Raw Data'!$E$2:$E$251,0)) -> Furniture | D35: =INDEX('Raw Data'!$I$2:$I$251,MATCH(A35,'Raw Data'!$E$2:$E$251,0)) -> 299.99 | E35: =COUNTIFS('Raw Data'!$E$2:$E$251,A35) -> 26 | F35: =SUMIFS('Raw Data'!$H$2:$H$251,'Raw Data'!$E$2:$E$251,A35) -> 78 | G35: =SUMIFS('Raw Data'!$N$2:$N$251,'Raw Data'!$E$2:$E$251,A35) -> 23399.22 | H35: =RANK(F35,$F$29:$F$38)+COUNTIF($F$29:F35,F35)-1 -> 6 | I35: =UPPER(LEFT(C35,3))&"-"&UPPER(LEFT(B35,3))&"-"&RIGHT(A35,2) -> FUR-DES-07
A36: P008 | B36: =INDEX('Raw Data'!$F$2:$F$251,MATCH(A36,'Raw Data'!$E$2:$E$251,0)) -> Bookshelf | C36: =INDEX('Raw Data'!$G$2:$G$251,MATCH(A36,'Raw Data'!$E$2:$E$251,0)) -> Furniture | D36: =INDEX('Raw Data'!$I$2:$I$251,MATCH(A36,'Raw Data'!$E$2:$E$251,0)) -> 149.99 | E36: =COUNTIFS('Raw Data'!$E$2:$E$251,A36) -> 35 | F36: =SUMIFS('Raw Data'!$H$2:$H$251,'Raw Data'!$E$2:$E$251,A36) -> 102 | G36: =SUMIFS('Raw Data'!$N$2:$N$251,'Raw Data'!$E$2:$E$251,A36) -> 15298.98 | H36: =RANK(F36,$F$29:$F$38)+COUNTIF($F$29:F36,F36)-1 -> 1 | I36: =UPPER(LEFT(C36,3))&"-"&UPPER(LEFT(B36,3))&"-"&RIGHT(A36,2) -> FUR-BOO-08
A37: P009 | B37: =INDEX('Raw Data'!$F$2:$F$251,MATCH(A37,'Raw Data'!$E$2:$E$251,0)) -> Monitor | C37: =INDEX('Raw Data'!$G$2:$G$251,MATCH(A37,'Raw Data'!$E$2:$E$251,0)) -> Electronics | D37: =INDEX('Raw Data'!$I$2:$I$251,MATCH(A37,'Raw Data'!$E$2:$E$251,0)) -> 249.99 | E37: =COUNTIFS('Raw Data'!$E$2:$E$251,A37) -> 26 | F37: =SUMIFS('Raw Data'!$H$2:$H$251,'Raw Data'!$E$2:$E$251,A37) -> 88 | G37: =SUMIFS('Raw Data'!$N$2:$N$251,'Raw Data'!$E$2:$E$251,A37) -> 21999.12 | H37: =RANK(F37,$F$29:$F$38)+COUNTIF($F$29:F37,F37)-1 -> 4 | I37: =UPPER(LEFT(C37,3))&"-"&UPPER(LEFT(B37,3))&"-"&RIGHT(A37,2) -> ELE-MON-09
A38: P010 | B38: =INDEX('Raw Data'!$F$2:$F$251,MATCH(A38,'Raw Data'!$E$2:$E$251,0)) -> Keyboard | C38: =INDEX('Raw Data'!$G$2:$G$251,MATCH(A38,'Raw Data'!$E$2:$E$251,0)) -> Electronics | D38: =INDEX('Raw Data'!$I$2:$I$251,MATCH(A38,'Raw Data'!$E$2:$E$251,0)) -> 89.99 | E38: =COUNTIFS('Raw Data'!$E$2:$E$251,A38) -> 34 | F38: =SUMIFS('Raw Data'!$H$2:$H$251,'Raw Data'!$E$2:$E$251,A38) -> 89 | G38: =SUMIFS('Raw Data'!$N$2:$N$251,'Raw Data'!$E$2:$E$251,A38) -> 8009.11 | H38: =RANK(F38,$F$29:$F$38)+COUNTIF($F$29:F38,F38)-1 -> 3 | I38: =UPPER(LEFT(C38,3))&"-"&UPPER(LEFT(B38,3))&"-"&RIGHT(A38,2) -> ELE-KEY-10
A39: Total | E39: =SUM(E29:E38) -> 250 | F39: =SUM(F29:F38) -> 753 | G39: =SUM(G29:G38) -> 229192.47
A41: Monthly Sales Trend
A42: Month Start | B42: Revenue | C42: Orders | D42: Units | E42: MoM % Change | F42: Month Label
A43: =EOMONTH(MIN('Raw Data'!$B$2:$B$251),-1)+1 -> 45383 | B43: =SUMIFS('Raw Data'!$N$2:$N$251,'Raw Data'!$B$2:$B$251,">="&A43,'Raw Data'!$B$2:$B$251,"<="&EOMONTH(A43,0)) -> 20919.33 | C43: =COUNTIFS('Raw Data'!$B$2:$B$251,">="&A43,'Raw Data'!$B$2:$B$251,"<="&EOMONTH(A43,0)) -> 21 | D43: =SUMIFS('Raw Data'!$H$2:$H$251,'Raw Data'!$B$2:$B$251,">="&A43,'Raw Data'!$B$2:$B$251,"<="&EOMONTH(A43,0)) -> 67 | F43: =TEXT(A43,"mmm-yy") -> Apr-24
A44: =EDATE(A43,1) -> 45413 | B44: =SUMIFS('Raw Data'!$N$2:$N$251,'Raw Data'!$B$2:$B$251,">="&A44,'Raw Data'!$B$2:$B$251,"<="&EOMONTH(A44,0)) -> 17039.35 | C44: =COUNTIFS('Raw Data'!$B$2:$B$251,">="&A44,'Raw Data'!$B$2:$B$251,"<="&EOMONTH(A44,0)) -> 19 | D44: =SUMIFS('Raw Data'!$H$2:$H$251,'Raw Data'!$B$2:$B$251,">="&A44,'Raw Data'!$B$2:$B$251,"<="&EOMONTH(A44,0)) -> 65 | E44: =IFERROR(B44/B43-1,0) -> -0.18547344 | F44: =TEXT(A44,"mmm-yy") -> May-24
A45: =EDATE(A44,1) -> 45444 | B45: =SUMIFS('Raw Data'!$N$2:$N$251,'Raw Data'!$B$2:$B$251,">="&A45,'Raw Data'!$B$2:$B$251,"<="&EOMONTH(A45,0)) -> 19299.45 | C45: =COUNTIFS('Raw Data'!$B$2:$B$251,">="&A45,'Raw Data'!$B$2:$B$251,"<="&EOMONTH(A45,0)) -> 19 | D45: =SUMIFS('Raw Data'!$H$2:$H$251,'Raw Data'!$B$2:$B$251,">="&A45,'Raw Data'!$B$2:$B$251,"<="&EOMONTH(A45,0)) -> 55 | E45: =IFERROR(B45/B44-1,0) -> 0.13264004 | F45: =TEXT(A45,"mmm-yy") -> Jun-24
...

Sheet Customer Analysis
A1: Customer Analysis – GroupBy (formulas), High-Value Customers, List Comparison, Abbreviations
A4: High-Value percentile (input) | B4: 0.8
A5: High-Value revenue threshold | B5: =PERCENTILE($G$8:$G$57,B4) -> 6557.8
A7: Customer_ID | B7: Customer_Name | C7: Initials | D7: Customer Code | E7: Orders | F7: Units | G7: Revenue | H7: Avg Order Value | I7: Revenue Rank | J7: Value Tier | K7: Electronics Orders | L7: Furniture Orders | M7: Elec_Seq | N7: Furn_Seq
A8: CUST001 | B8: =INDEX('Raw Data'!$D$2:$D$251,MATCH(A8,'Raw Data'!$C$2:$C$251,0)) -> John Smith | C8: =UPPER(LEFT(B8,1))&UPPER(MID(B8,FIND(" ",B8)+1,1)) -> JS | D8: =C8&"-"&TEXT(VALUE(RIGHT(A8,3)),"000") -> JS-001 | E8: =COUNTIFS('Raw Data'!$C$2:$C$251,A8) -> 1 | F8: =SUMIFS('Raw Data'!$H$2:$H$251,'Raw Data'!$C$2:$C$251,A8) -> 4 | G8: =SUMIFS('Raw Data'!$N$2:$N$251,'Raw Data'!$C$2:$C$251,A8) -> 599.96 | H8: =IFERROR(G8/E8,0) -> 599.96 | I8: =RANK(G8,$G$8:$G$57)+COUNTIF($G$8:G8,G8)-1 -> 47 | J8: =IF(G8>=$B$5,"High-Value",IF(G8>=MEDIAN($G$8:$G$57),"Mid-Value","Low-Value")) -> Low-Value | K8: =COUNTIFS('Raw Data'!$C$2:$C$251,A8,'Raw Data'!$G$2:$G$251,"Electronics") -> 0 | L8: =COUNTIFS('Raw Data'!$C$2:$C$251,A8,'Raw Data'!$G$2:$G$251,"Furniture") -> 1 | M8: =IF(K8>0,COUNTIF($K$8:K8,">0"),"") | N8: =IF(L8>0,COUNTIF($L$8:L8,">0"),"") -> 1
A9: CUST002 | B9: =INDEX('Raw Data'!$D$2:$D$251,MATCH(A9,'Raw Data'!$C$2:$C$251,0)) -> Emma Wilson | C9: =UPPER(LEFT(B9,1))&UPPER(MID(B9,FIND(" ",B9)+1,1)) -> EW | D9: =C9&"-"&TEXT(VALUE(RIGHT(A9,3)),"000") -> EW-002 | E9: =COUNTIFS('Raw Data'!$C$2:$C$251,A9) -> 5 | F9: =SUMIFS('Raw Data'!$H$2:$H$251,'Raw Data'!$C$2:$C$251,A9) -> 12 | G9: =SUMIFS('Raw Data'!$N$2:$N$251,'Raw Data'!$C$2:$C$251,A9) -> 1229.88 | H9: =IFERROR(G9/E9,0) -> 245.976 | I9: =RANK(G9,$G$8:$G$57)+COUNTIF($G$8:G9,G9)-1 -> 44 | J9: =IF(G9>=$B$5,"High-Value",IF(G9>=MEDIAN($G$8:$G$57),"Mid-Value","Low-Value")) -> Low-Value | K9: =COUNTIFS('Raw Data'!$C$2:$C$251,A9,'Raw Data'!$G$2:$G$251,"Electronics") -> 1 | L9: =COUNTIFS('Raw Data'!$C$2:$C$251,A9,'Raw Data'!$G$2:$G$251,"Furniture") -> 2 | M9: =IF(K9>0,COUNTIF($K$8:K9,">0"),"") -> 1 | N9: =IF(L9>0,COUNTIF($L$8:L9,">0"),"") -> 2
A10: CUST003 | B10: =INDEX('Raw Data'!$D$2:$D$251,MATCH(A10,'Raw Data'!$C$2:$C$251,0)) -> Michael Brown | C10: =UPPER(LEFT(B10,1))&UPPER(MID(B10,FIND(" ",B10)+1,1)) -> MB | D10: =C10&"-"&TEXT(VALUE(RIGHT(A10,3)),"000") -> MB-003 | E10: =COUNTIFS('Raw Data'!$C$2:$C$251,A10) -> 9 | F10: =SUMIFS('Raw Data'!$H$2:$H$251,'Raw Data'!$C$2:$C$251,A10) -> 26 | G10: =SUMIFS('Raw Data'!$N$2:$N$251,'Raw Data'!$C$2:$C$251,A10) -> 6169.74 | H10: =IFERROR(G10/E10,0) -> 685.52667 | I10: =RANK(G10,$G$8:$G$57)+COUNTIF($G$8:G10,G10)-1 -> 14 | J10: =IF(G10>=$B$5,"High-Value",IF(G10>=MEDIAN($G$8:$G$57),"Mid-Value","Low-Value")) -> Mid-Value | K10: =COUNTIFS('Raw Data'!$C$2:$C$251,A10,'Raw Data'!$G$2:$G$251,"Electronics") -> 2 | L10: =COUNTIFS('Raw Data'!$C$2:$C$251,A10,'Raw Data'!$G$2:$G$251,"Furniture") -> 7 | M10: =IF(K10>0,COUNTIF($K$8:K10,">0"),"") -> 2 | N10: =IF(L10>0,COUNTIF($L$8:L10,">0"),"") -> 3
A11: CUST004 | B11: =INDEX('Raw Data'!$D$2:$D$251,MATCH(A11,'Raw Data'!$C$2:$C$251,0)) -> Sarah Davis | C11: =UPPER(LEFT(B11,1))&UPPER(MID(B11,FIND(" ",B11)+1,1)) -> SD | D11: =C11&"-"&TEXT(VALUE(RIGHT(A11,3)),"000") -> SD-004 | E11: =COUNTIFS('Raw Data'!$C$2:$C$251,A11) -> 5 | F11: =SUMIFS('Raw Data'!$H$2:$H$251,'Raw Data'!$C$2:$C$251,A11) -> 19 | G11: =SUMIFS('Raw Data'!$N$2:$N$251,'Raw Data'!$C$2:$C$251,A11) -> 5499.81 | H11: =IFERROR(G11/E11,0) -> 1099.962 | I11: =RANK(G11,$G$8:$G$57)+COUNTIF($G$8:G11,G11)-1 -> 19 | J11: =IF(G11>=$B$5,"High-Value",IF(G11>=MEDIAN($G$8:$G$57),"Mid-Value","Low-Value")) -> Mid-Value | K11: =COUNTIFS('Raw Data'!$C$2:$C$251,A11,'Raw Data'!$G$2:$G$251,"Electronics") -> 3 | L11: =COUNTIFS('Raw Data'!$C$2:$C$251,A11,'Raw Data'!$G$2:$G$251,"Furniture") -> 2 | M11: =IF(K11>0,COUNTIF($K$8:K11,">0"),"") -> 3 | N11: =IF(L11>0,COUNTIF($L$8:L11,">0"),"") -> 4
A12: CUST005 | B12: =INDEX('Raw Data'!$D$2:$D$251,MATCH(A12,'Raw Data'!$C$2:$C$251,0)) -> James Johnson | C12: =UPPER(LEFT(B12,1))&UPPER(MID(B12,FIND(" ",B12)+1,1)) -> JJ | D12: =C12&"-"&TEXT(VALUE(RIGHT(A12,3)),"000") -> JJ-005 | E12: =COUNTIFS('Raw Data'!$C$2:$C$251,A12) -> 1 | F12: =SUMIFS('Raw Data'!$H$2:$H$251,'Raw Data'!$C$2:$C$251,A12) -> 3 | G12: =SUMIFS('Raw Data'!$N$2:$N$251,'Raw Data'!$C$2:$C$251,A12) -> 179.97 | H12: =IFERROR(G12/E12,0) -> 179.97 | I12: =RANK(G12,$G$8:$G$57)+COUNTIF($G$8:G12,G12)-1 -> 50 | J12: =IF(G12>=$B$5,"High-Value",IF(G12>=MEDIAN($G$8:$G$57),"Mid-Value","Low-Value")) -> Low-Value | K12: =COUNTIFS('Raw Data'!$C$2:$C$251,A12,'Raw Data'!$G$2:$G$251,"Electronics") -> 0 | L12: =COUNTIFS('Raw Data'!$C$2:$C$251,A12,'Raw Data'!$G$2:$G$251,"Furniture") -> 0 | M12: =IF(K12>0,COUNTIF($K$8:K12,">0"),"") | N12: =IF(L12>0,COUNTIF($L$8:L12,">0"),"")
A13: CUST006 | B13: =INDEX('Raw Data'!$D$2:$D$251,MATCH(A13,'Raw Data'!$C$2:$C$251,0)) -> Lisa Anderson | C13: =UPPER(LEFT(B13,1))&UPPER(MID(B13,FIND(" ",B13)+1,1)) -> LA | D13: =C13&"-"&TEXT(VALUE(RIGHT(A13,3)),"000") -> LA-006 | E13: =COUNTIFS('Raw Data'!$C$2:$C$251,A13) -> 5 | F13: =SUMIFS('Raw Data'!$H$2:$H$251,'Raw Data'!$C$2:$C$251,A13) -> 20 | G13: =SUMIFS('Raw Data'!$N$2:$N$251,'Raw Data'!$C$2:$C$251,A13) -> 2039.8 | H13: =IFERROR(G13/E13,0) -> 407.96 | I13: =RANK(G13,$G$8:$G$57)+COUNTIF($G$8:G13,G13)-1 -> 36 | J13: =IF(G13>=$B$5,"High-Value",IF(G13>=MEDIAN($G$8:$G$57),"Mid-Value","Low-Value")) -> Low-Value | K13: =COUNTIFS('Raw Data'!$C$2:$C$251,A13,'Raw Data'!$G$2:$G$251,"Electronics") -> 2 | L13: =COUNTIFS('Raw Data'!$C$2:$C$251,A13,'Raw Data'!$G$2:$G$251,"Furniture") -> 1 | M13: =IF(K13>0,COUNTIF($K$8:K13,">0"),"") -> 4 | N13: =IF(L13>0,COUNTIF($L$8:L13,">0"),"") -> 5
A14: CUST007 | B14: =INDEX('Raw Data'!$D$2:$D$251,MATCH(A14,'Raw Data'!$C$2:$C$251,0)) -> David Martinez | C14: =UPPER(LEFT(B14,1))&UPPER(MID(B14,FIND(" ",B14)+1,1)) -> DM | D14: =C14&"-"&TEXT(VALUE(RIGHT(A14,3)),"000") -> DM-007 | E14: =COUNTIFS('Raw Data'!$C$2:$C$251,A14) -> 6 | F14: =SUMIFS('Raw Data'!$H$2:$H$251,'Raw Data'!$C$2:$C$251,A14) -> 16 | G14: =SUMIFS('Raw Data'!$N$2:$N$251,'Raw Data'!$C$2:$C$251,A14) -> 1809.84 | H14: =IFERROR(G14/E14,0) -> 301.64 | I14: =RANK(G14,$G$8:$G$57)+COUNTIF($G$8:G14,G14)-1 -> 39 | J14: =IF(G14>=$B$5,"High-Value",IF(G14>=MEDIAN($G$8:$G$57),"Mid-Value","Low-Value")) -> Low-Value | K14: =COUNTIFS('Raw Data'!$C$2:$C$251,A14,'Raw Data'!$G$2:$G$251,"Electronics") -> 2 | L14: =COUNTIFS('Raw Data'!$C$2:$C$251,A14,'Raw Data'!$G$2:$G$251,"Furniture") -> 2 | M14: =IF(K14>0,COUNTIF($K$8:K14,">0"),"") -> 5 | N14: =IF(L14>0,COUNTIF($L$8:L14,">0"),"") -> 6
A15: CUST008 | B15: =INDEX('Raw Data'!$D$2:$D$251,MATCH(A15,'Raw Data'!$C$2:$C$251,0)) -> Jennifer Taylor | C15: =UPPER(LEFT(B15,1))&UPPER(MID(B15,FIND(" ",B15)+1,1)) -> JT | D15: =C15&"-"&TEXT(VALUE(RIGHT(A15,3)),"000") -> JT-008 | E15: =COUNTIFS('Raw Data'!$C$2:$C$251,A15) -> 4 | F15: =SUMIFS('Raw Data'!$H$2:$H$251,'Raw Data'!$C$2:$C$251,A15) -> 15 | G15: =SUMIFS('Raw Data'!$N$2:$N$251,'Raw Data'!$C$2:$C$251,A15) -> 4739.85 | H15: =IFERROR(G15/E15,0) -> 1184.9625 | I15: =RANK(G15,$G$8:$G$57)+COUNTIF($G$8:G15,G15)-1 -> 24 | J15: =IF(G15>=$B$5,"High-Value",IF(G15>=MEDIAN($G$8:$G$57),"Mid-Value","Low-Value")) -> Mid-Value | K15: =COUNTIFS('Raw Data'!$C$2:$C$251,A15,'Raw Data'!$G$2:$G$251,"Electronics") -> 1 | L15: =COUNTIFS('Raw Data'!$C$2:$C$251,A15,'Raw Data'!$G$2:$G$251,"Furniture") -> 1 | M15: =IF(K15>0,COUNTIF($K$8:K15,">0"),"") -> 6 | N15: =IF(L15>0,COUNTIF($L$8:L15,">0"),"") -> 7
A16: CUST009 | B16: =INDEX('Raw Data'!$D$2:$D$251,MATCH(A16,'Raw Data'!$C$2:$C$251,0)) -> Robert Thomas | C16: =UPPER(LEFT(B16,1))&UPPER(MID(B16,FIND(" ",B16)+1,1)) -> RT | D16: =C16&"-"&TEXT(VALUE(RIGHT(A16,3)),"000") -> RT-009 | E16: =COUNTIFS('Raw Data'!$C$2:$C$251,A16) -> 5 | F16: =SUMIFS('Raw Data'!$H$2:$H$251,'Raw Data'!$C$2:$C$251,A16) -> 10 | G16: =SUMIFS('Raw Data'!$N$2:$N$251,'Raw Data'!$C$2:$C$251,A16) -> 3509.9 | H16: =IFERROR(G16/E16,0) -> 701.98 | I16: =RANK(G16,$G$8:$G$57)+COUNTIF($G$8:G16,G16)-1 -> 32 | J16: =IF(G16>=$B$5,"High-Value",IF(G16>=MEDIAN($G$8:$G$57),"Mid-Value","Low-Value")) -> Low-Value | K16: =COUNTIFS('Raw Data'!$C$2:$C$251,A16,'Raw Data'!$G$2:$G$251,"Electronics") -> 4 | L16: =COUNTIFS('Raw Data'!$C$2:$C$251,A16,'Raw Data'!$G$2:$G$251,"Furniture") -> 1 | M16: =IF(K16>0,COUNTIF($K$8:K16,">0"),"") -> 7 | N16: =IF(L16>0,COUNTIF($L$8:L16,">0"),"") -> 8
A17: CUST010 | B17: =INDEX('Raw Data'!$D$2:$D$251,MATCH(A17,'Raw Data'!$C$2:$C$251,0)) -> Maria Garcia | C17: =UPPER(LEFT(B17,1))&UPPER(MID(B17,FIND(" ",B17)+1,1)) -> MG | D17: =C17&"-"&TEXT(VALUE(RIGHT(A17,3)),"000") -> MG-010 | E17: =COUNTIFS('Raw Data'!$C$2:$C$251,A17) -> 4 | F17: =SUMIFS('Raw Data'!$H$2:$H$251,'Raw Data'!$C$2:$C$251,A17) -> 7 | G17: =SUMIFS('Raw Data'!$N$2:$N$251,'Raw Data'!$C$2:$C$251,A17) -> 1909.93 | H17: =IFERROR(G17/E17,0) -> 477.4825 | I17: =RANK(G17,$G$8:$G$57)+COUNTIF($G$8:G17,G17)-1 -> 38 | J17: =IF(G17>=$B$5,"High-Value",IF(G17>=MEDIAN($G$8:$G$57),"Mid-Value","Low-Value")) -> Low-Value | K17: =COUNTIFS('Raw Data'!$C$2:$C$251,A17,'Raw Data'!$G$2:$G$251,"Electronics") -> 2 | L17: =COUNTIFS('Raw Data'!$C$2:$C$251,A17,'Raw Data'!$G$2:$G$251,"Furniture") -> 1 | M17: =IF(K17>0,COUNTIF($K$8:K17,">0"),"") -> 8 | N17: =IF(L17>0,COUNTIF($L$8:L17,">0"),"") -> 9
A18: CUST011 | B18: =INDEX('Raw Data'!$D$2:$D$251,MATCH(A18,'Raw Data'!$C$2:$C$251,0)) -> William White | C18: =UPPER(LEFT(B18,1))&UPPER(MID(B18,FIND(" ",B18)+1,1)) -> WW | D18: =C18&"-"&TEXT(VALUE(RIGHT(A18,3)),"000") -> WW-011 | E18: =COUNTIFS('Raw Data'!$C$2:$C$251,A18) -> 3 | F18: =SUMIFS('Raw Data'!$H$2:$H$251,'Raw Data'!$C$2:$C$251,A18) -> 9 | G18: =SUMIFS('Raw Data'!$N$2:$N$251,'Raw Data'!$C$2:$C$251,A18) -> 4749.91 | H18: =IFERROR(G18/E18,0) -> 1583.3033 | I18: =RANK(G18,$G$8:$G$57)+COUNTIF($G$8:G18,G18)-1 -> 23 | J18: =IF(G18>=$B$5,"High-Value",IF(G18>=MEDIAN($G$8:$G$57),"Mid-Value","Low-Value")) -> Mid-Value | K18: =COUNTIFS('Raw Data'!$C$2:$C$251,A18,'Raw Data'!$G$2:$G$251,"Electronics") -> 3 | L18: =COUNTIFS('Raw Data'!$C$2:$C$251,A18,'Raw Data'!$G$2:$G$251,"Furniture") -> 0 | M18: =IF(K18>0,COUNTIF($K$8:K18,">0"),"") -> 9 | N18: =IF(L18>0,COUNTIF($L$8:L18,">0"),"")
A19: CUST012 | B19: =INDEX('Raw Data'!$D$2:$D$251,MATCH(A19,'Raw Data'!$C$2:$C$251,0)) -> Patricia Moore | C19: =UPPER(LEFT(B19,1))&UPPER(MID(B19,FIND(" ",B19)+1,1)) -> PM | D19: =C19&"-"&TEXT(VALUE(RIGHT(A19,3)),"000") -> PM-012 | E19: =COUNTIFS('Raw Data'!$C$2:$C$251,A19) -> 8 | F19: =SUMIFS('Raw Data'!$H$2:$H$251,'Raw Data'!$C$2:$C$251,A19) -> 27 | G19: =SUMIFS('Raw Data'!$N$2:$N$251,'Raw Data'!$C$2:$C$251,A19) -> 9799.73 | H19: =IFERROR(G19/E19,0) -> 1224.9662 | I19: =RANK(G19,$G$8:$G$57)+COUNTIF($G$8:G19,G19)-1 -> 4 | J19: =IF(G19>=$B$5,"High-Value",IF(G19>=MEDIAN($G$8:$G$57),"Mid-Value","Low-Value")) -> High-Value | K19: =COUNTIFS('Raw Data'!$C$2:$C$251,A19,'Raw Data'!$G$2:$G$251,"Electronics") -> 6 | L19: =COUNTIFS('Raw Data'!$C$2:$C$251,A19,'Raw Data'!$G$2:$G$251,"Furniture") -> 2 | M19: =IF(K19>0,COUNTIF($K$8:K19,">0"),"") -> 10 | N19: =IF(L19>0,COUNTIF($L$8:L19,">0"),"") -> 10
... A57: CUST050 | B57: =INDEX('Raw Data'!$D$2:$D$251,MATCH(A57,'Raw Data'!$C$2:$C$251,0)) -> Julie Foster | C57: =UPPER(LEFT(B57,1))&UPPER(MID(B57,FIND(" ",B57)+1,1)) -> JF | D57: =C57&"-"&TEXT(VALUE(RIGHT(A57,3)),"000") -> JF-050 | E57: =COUNTIFS('Raw Data'!$C$2:$C$251,A57) -> 1 | F57: =SUMIFS('Raw Data'!$H$2:$H$251,'Raw Data'!$C$2:$C$251,A57) -> 4 | G57: =SUMIFS('Raw Data'!$N$2:$N$251,'Raw Data'!$C$2:$C$251,A57) -> 239.96 | H57: =IFERROR(G57/E57,0) -> 239.96 | I57: =RANK(G57,$G$8:$G$57)+COUNTIF($G$8:G57,G57)-1 -> 49 | J57: =IF(G57>=$B$5,"High-Value",IF(G57>=MEDIAN($G$8:$G$57),"Mid-Value","Low-Value")) -> Low-Value | K57: =COUNTIFS('Raw Data'!$C$2:$C$251,A57,'Raw Data'!$G$2:$G$251,"Electronics") -> 0 | L57: =COUNTIFS('Raw Data'!$C$2:$C$251,A57,'Raw Data'!$G$2:$G$251,"Furniture") -> 0 | M57: =IF(K57>0,COUNTIF($K$8:K57,">0"),"") | N57: =IF(L57>0,COUNTIF($L$8:L57,">0"),"")
A61: Top 10 Customers by Revenue
A62: Rank | B62: Customer_Name | C62: Revenue | D62: Orders | E62: Value Tier | F62: % of Total Revenue | H62: Value Tier | I62: Customers | J62: Revenue | K62: % of Revenue
A63: 1 | B63: =INDEX($B$8:$B$57,MATCH($A63,$I$8:$I$57,0)) -> Mark Carter | C63: =INDEX($G$8:$G$57,MATCH($A63,$I$8:$I$57,0)) -> 15659.65 | D63: =INDEX($E$8:$E$57,MATCH($A63,$I$8:$I$57,0)) -> 12 | E63: =INDEX($J$8:$J$57,MATCH($A63,$I$8:$I$57,0)) -> High-Value | F63: =C63/SUM($G$8:$G$57) -> 0.068325325 | H63: High-Value | I63: =COUNTIF($J$8:$J$57,H63) -> 10 | J63: =SUMIFS($G$8:$G$57,$J$8:$J$57,H63) -> 93867.66 | K63: =J63/SUM($G$8:$G$57) -> 0.40955822
A64: 2 | B64: =INDEX($B$8:$B$57,MATCH($A64,$I$8:$I$57,0)) -> Edward Mitchell | C64: =INDEX($G$8:$G$57,MATCH($A64,$I$8:$I$57,0)) -> 11919.77 | D64: =INDEX($E$8:$E$57,MATCH($A64,$I$8:$I$57,0)) -> 6 | E64: =INDEX($J$8:$J$57,MATCH($A64,$I$8:$I$57,0)) -> High-Value | F64: =C64/SUM($G$8:$G$57) -> 0.052007686 | H64: Mid-Value | I64: =COUNTIF($J$8:$J$57,H64) -> 15 | J64: =SUMIFS($G$8:$G$57,$J$8:$J$57,H64) -> 82107.47 | K64: =J64/SUM($G$8:$G$57) -> 0.3582468
A65: 3 | B65: =INDEX($B$8:$B$57,MATCH($A65,$I$8:$I$57,0)) -> Barbara Young | C65: =INDEX($G$8:$G$57,MATCH($A65,$I$8:$I$57,0)) -> 10649.8 | D65: =INDEX($E$8:$E$57,MATCH($A65,$I$8:$I$57,0)) -> 5 | E65: =INDEX($J$8:$J$57,MATCH($A65,$I$8:$I$57,0)) -> High-Value | F65: =C65/SUM($G$8:$G$57) -> 0.046466623 | H65: Low-Value | I65: =COUNTIF($J$8:$J$57,H65) -> 25 | J65: =SUMIFS($G$8:$G$57,$J$8:$J$57,H65) -> 53217.34 | K65: =J65/SUM($G$8:$G$57) -> 0.23219498
A66: 4 | B66: =INDEX($B$8:$B$57,MATCH($A66,$I$8:$I$57,0)) -> Patricia Moore | C66: =INDEX($G$8:$G$57,MATCH($A66,$I$8:$I$57,0)) -> 9799.73 | D66: =INDEX($E$8:$E$57,MATCH($A66,$I$8:$I$57,0)) -> 8 | E66: =INDEX($J$8:$J$57,MATCH($A66,$I$8:$I$57,0)) -> High-Value | F66: =C66/SUM($G$8:$G$57) -> 0.042757644 | H66: Total | I66: =SUM(I63:I65) -> 50 | J66: =SUM(J63:J65) -> 229192.47 | K66: =SUM(K63:K65) -> 1
A67: 5 | B67: =INDEX($B$8:$B$57,MATCH($A67,$I$8:$I$57,0)) -> Paul Baker | C67: =INDEX($G$8:$G$57,MATCH($A67,$I$8:$I$57,0)) -> 8309.74 | D67: =INDEX($E$8:$E$57,MATCH($A67,$I$8:$I$57,0)) -> 8 | E67: =INDEX($J$8:$J$57,MATCH($A67,$I$8:$I$57,0)) -> High-Value | F67: =C67/SUM($G$8:$G$57) -> 0.036256601
A68: 6 | B68: =INDEX($B$8:$B$57,MATCH($A68,$I$8:$I$57,0)) -> Dorothy Nelson | C68: =INDEX($G$8:$G$57,MATCH($A68,$I$8:$I$57,0)) -> 8269.79 | D68: =INDEX($E$8:$E$57,MATCH($A68,$I$8:$I$57,0)) -> 6 | E68: =INDEX($J$8:$J$57,MATCH($A68,$I$8:$I$57,0)) -> High-Value | F68: =C68/SUM($G$8:$G$57) -> 0.036082294
A69: 7 | B69: =INDEX($B$8:$B$57,MATCH($A69,$I$8:$I$57,0)) -> Karen Hill | C69: =INDEX($G$8:$G$57,MATCH($A69,$I$8:$I$57,0)) -> 8009.77 | D69: =INDEX($E$8:$E$57,MATCH($A69,$I$8:$I$57,0)) -> 8 | E69: =INDEX($J$8:$J$57,MATCH($A69,$I$8:$I$57,0)) -> High-Value | F69: =C69/SUM($G$8:$G$57) -> 0.034947789
A70: 8 | B70: =INDEX($B$8:$B$57,MATCH($A70,$I$8:$I$57,0)) -> Daniel King | C70: =INDEX($G$8:$G$57,MATCH($A70,$I$8:$I$57,0)) -> 7309.8 | D70: =INDEX($E$8:$E$57,MATCH($A70,$I$8:$I$57,0)) -> 7 | E70: =INDEX($J$8:$J$57,MATCH($A70,$I$8:$I$57,0)) -> High-Value | F70: =C70/SUM($G$8:$G$57) -> 0.031893718
A71: 9 | B71: =INDEX($B$8:$B$57,MATCH($A71,$I$8:$I$57,0)) -> Lawrence Reed | C71: =INDEX($G$8:$G$57,MATCH($A71,$I$8:$I$57,0)) -> 6989.77 | D71: =INDEX($E$8:$E$57,MATCH($A71,$I$8:$I$57,0)) -> 8 | E71: =INDEX($J$8:$J$57,MATCH($A71,$I$8:$I$57,0)) -> High-Value | F71: =C71/SUM($G$8:$G$57) -> 0.030497381
A72: 10 | B72: =INDEX($B$8:$B$57,MATCH($A72,$I$8:$I$57,0)) -> Joseph Jackson | C72: =INDEX($G$8:$G$57,MATCH($A72,$I$8:$I$57,0)) -> 6949.84 | D72: =INDEX($E$8:$E$57,MATCH($A72,$I$8:$I$57,0)) -> 5 | E72: =INDEX($J$8:$J$57,MATCH($A72,$I$8:$I$57,0)) -> High-Value | F72: =C72/SUM($G$8:$G$57) -> 0.03032316
A76: Compare Two Lists – extract matching names into a new column
A77: List A: Electronics buyers | B77: List B: Furniture buyers | C77: Matching names (in A and B) | E77: Count A | F77: Count B | G77: Matches
A78: =IFERROR(INDEX($B$8:$B$57,MATCH(ROWS($A$78:A78),$M$8:$M$57,0)),"") -> Emma Wilson | B78: =IFERROR(INDEX($B$8:$B$57,MATCH(ROWS($B$78:B78),$N$8:$N$57,0)),"") -> John Smith | C78: =IF(A78="","",IF(ISNUMBER(MATCH(A78,$B$78:$B$127,0)),A78,"")) -> Emma Wilson | E78: =COUNTIF(A78:A127,"?*") -> 44 | F78: =COUNTIF(B78:B127,"?*") -> 37 | G78: =COUNTIF(C78:C127,"?*") -> 34
A79: =IFERROR(INDEX($B$8:$B$57,MATCH(ROWS($A$78:A79),$M$8:$M$57,0)),"") -> Michael Brown | B79: =IFERROR(INDEX($B$8:$B$57,MATCH(ROWS($B$78:B79),$N$8:$N$57,0)),"") -> Emma Wilson | C79: =IF(A79="","",IF(ISNUMBER(MATCH(A79,$B$78:$B$127,0)),A79,"")) -> Michael Brown
A80: =IFERROR(INDEX($B$8:$B$57,MATCH(ROWS($A$78:A80),$M$8:$M$57,0)),"") -> Sarah Davis | B80: =IFERROR(INDEX($B$8:$B$57,MATCH(ROWS($B$78:B80),$N$8:$N$57,0)),"") -> Michael Brown | C80: =IF(A80="","",IF(ISNUMBER(MATCH(A80,$B$78:$B$127,0)),A80,"")) -> Sarah Davis
A81: =IFERROR(INDEX($B$8:$B$57,MATCH(ROWS($A$78:A81),$M$8:$M$57,0)),"") -> Lisa Anderson | B81: =IFERROR(INDEX($B$8:$B$57,MATCH(ROWS($B$78:B81),$N$8:$N$57,0)),"") -> Sarah Davis | C81: =IF(A81="","",IF(ISNUMBER(MATCH(A81,$B$78:$B$127,0)),A81,"")) -> Lisa Anderson
A82: =IFERROR(INDEX($B$8:$B$57,MATCH(ROWS($A$78:A82),$M$8:$M$57,0)),"") -> David Martinez | B82: =IFERROR(INDEX($B$8:$B$57,MATCH(ROWS($B$78:B82),$N$8:$N$57,0)),"") -> Lisa Anderson | C82: =IF(A82="","",IF(ISNUMBER(MATCH(A82,$B$78:$B$127,0)),A82,"")) -> David Martinez
A83: =IFERROR(INDEX($B$8:$B$57,MATCH(ROWS($A$78:A83),$M$8:$M$57,0)),"") -> Jennifer Taylor | B83: =IFERROR(INDEX($B$8:$B$57,MATCH(ROWS($B$78:B83),$N$8:$N$57,0)),"") -> David Martinez | C83: =IF(A83="","",IF(ISNUMBER(MATCH(A83,$B$78:$B$127,0)),A83,"")) -> Jennifer Taylor
A84: =IFERROR(INDEX($B$8:$B$57,MATCH(ROWS($A$78:A84),$M$8:$M$57,0)),"") -> Robert Thomas | B84: =IFERROR(INDEX($B$8:$B$57,MATCH(ROWS($B$78:B84),$N$8:$N$57,0)),"") -> Jennifer Taylor | C84: =IF(A84="","",IF(ISNUMBER(MATCH(A84,$B$78:$B$127,0)),A84,"")) -> Robert Thomas
A85: =IFERROR(INDEX($B$8:$B$57,MATCH(ROWS($A$78:A85),$M$8:$M$57,0)),"") -> Maria Garcia | B85: =IFERROR(INDEX($B$8:$B$57,MATCH(ROWS($B$78:B85),$N$8:$N$57,0)),"") -> Robert Thomas | C85: =IF(A85="","",IF(ISNUMBER(MATCH(A85,$B$78:$B$127,0)),A85,"")) -> Maria Garcia
A86: =IFERROR(INDEX($B$8:$B$57,MATCH(ROWS($A$78:A86),$M$8:$M$57,0)),"") -> William White | B86: =IFERROR(INDEX($B$8:$B$57,MATCH(ROWS($B$78:B86),$N$8:$N$57,0)),"") -> Maria Garcia | C86: =IF(A86="","",IF(ISNUMBER(MATCH(A86,$B$78:$B$127,0)),A86,""))
...

Sheet DateTime_Filter
A1: Date & Time Functions • FILTER • Timestamp
A3: 1. Date & Time Functions: TODAY, NOW, DATEDIF, EOMONTH
A4: Item | B4: Result | C4: Function used
A5: Today | B5: =TODAY() -> 46324 | C5: TODAY()
A6: Now (date & time) | B6: =NOW() -> 46324.949 | C6: NOW()
A7: First transaction date | B7: =MIN('Raw Data'!$B$2:$B$251) -> 45393 | C7: MIN
A8: Last transaction date | B8: =MAX('Raw Data'!$B$2:$B$251) -> 45758 | C8: MAX
A9: Years covered (first to last) | B9: =DATEDIF(B7,B8,"Y") -> 1 | C9: DATEDIF(...,"Y")
A10: Months covered | B10: =DATEDIF(B7,B8,"M") -> 12 | C10: DATEDIF(...,"M")
A11: Days covered | B11: =DATEDIF(B7,B8,"D") -> 365 | C11: DATEDIF(...,"D")
A12: Oldest customer tenure to today (years) | B12: =DATEDIF(MIN('Raw Data'!$M$2:$M$251),TODAY(),"Y") -> 5 | C12: DATEDIF(Customer_Since, TODAY())
A13: Month-end of last transaction | B13: =EOMONTH(B8,0) -> 45777 | C13: EOMONTH(date,0)
A14: Month-end of current month | B14: =EOMONTH(TODAY(),0) -> 46326 | C14: EOMONTH(TODAY(),0)
A15: Days left in current month | B15: =B14-B5 -> 2 | C15: EOMONTH - TODAY
A16: Days since last transaction | B16: =TODAY()-B8 -> 566 | C16: TODAY - MAX(date)
A19: 2. FILTER – multi-value return (dynamic extraction of matching rows)
A21: Region (select) | C21: North
A22: Minimum Total_Amount | C22: 1000
A23: Matching rows | C23: =MAX('Raw Data'!$U$2:$U$251) -> 14
A26: Transaction_ID | B26: Date | C26: Customer_Name | D26: Product_Name | E26: Region | F26: Quantity | G26: Total_Amount
A27: =IFERROR(INDEX('Raw Data'!$A$2:$A$251,MATCH(ROWS($A$27:$A27),'Raw Data'!$U$2:$U$251,0)),"") -> TRX0134 | B27: =IFERROR(INDEX('Raw Data'!$B$2:$B$251,MATCH(ROWS($A$27:$A27),'Raw Data'!$U$2:$U$251,0)),"") -> 45410 | C27: =IFERROR(INDEX('Raw Data'!$D$2:$D$251,MATCH(ROWS($A$27:$A27),'Raw Data'!$U$2:$U$251,0)),"") -> Maria Garcia | D27: =IFERROR(INDEX('Raw Data'!$F$2:$F$251,MATCH(ROWS($A$27:$A27),'Raw Data'!$U$2:$U$251,0)),"") -> Smartphone | E27: =IFERROR(INDEX('Raw Data'!$K$2:$K$251,MATCH(ROWS($A$27:$A27),'Raw Data'!$U$2:$U$251,0)),"") -> North | F27: =IFERROR(INDEX('Raw Data'!$H$2:$H$251,MATCH(ROWS($A$27:$A27),'Raw Data'!$U$2:$U$251,0)),"") -> 2 | G27: =IFERROR(INDEX('Raw Data'!$N$2:$N$251,MATCH(ROWS($A$27:$A27),'Raw Data'!$U$2:$U$251,0)),"") -> 1399.98
A28: =IFERROR(INDEX('Raw Data'!$A$2:$A$251,MATCH(ROWS($A$27:$A28),'Raw Data'!$U$2:$U$251,0)),"") -> TRX0217 | B28: =IFERROR(INDEX('Raw Data'!$B$2:$B$251,MATCH(ROWS($A$27:$A28),'Raw Data'!$U$2:$U$251,0)),"") -> 45503 | C28: =IFERROR(INDEX('Raw Data'!$D$2:$D$251,MATCH(ROWS($A$27:$A28),'Raw Data'!$U$2:$U$251,0)),"") -> Mark Carter | D28: =IFERROR(INDEX('Raw Data'!$F$2:$F$251,MATCH(ROWS($A$27:$A28),'Raw Data'!$U$2:$U$251,0)),"") -> Smartphone | E28: =IFERROR(INDEX('Raw Data'!$K$2:$K$251,MATCH(ROWS($A$27:$A28),'Raw Data'!$U$2:$U$251,0)),"") -> North | F28: =IFERROR(INDEX('Raw Data'!$H$2:$H$251,MATCH(ROWS($A$27:$A28),'Raw Data'!$U$2:$U$251,0)),"") -> 2 | G28: =IFERROR(INDEX('Raw Data'!$N$2:$N$251,MATCH(ROWS($A$27:$A28),'Raw Data'!$U$2:$U$251,0)),"") -> 1399.98
A29: =IFERROR(INDEX('Raw Data'!$A$2:$A$251,MATCH(ROWS($A$27:$A29),'Raw Data'!$U$2:$U$251,0)),"") -> TRX0205 | B29: =IFERROR(INDEX('Raw Data'!$B$2:$B$251,MATCH(ROWS($A$27:$A29),'Raw Data'!$U$2:$U$251,0)),"") -> 45515 | C29: =IFERROR(INDEX('Raw Data'!$D$2:$D$251,MATCH(ROWS($A$27:$A29),'Raw Data'!$U$2:$U$251,0)),"") -> Mark Carter | D29: =IFERROR(INDEX('Raw Data'!$F$2:$F$251,MATCH(ROWS($A$27:$A29),'Raw Data'!$U$2:$U$251,0)),"") -> Desk | E29: =IFERROR(INDEX('Raw Data'!$K$2:$K$251,MATCH(ROWS($A$27:$A29),'Raw Data'!$U$2:$U$251,0)),"") -> North | F29: =IFERROR(INDEX('Raw Data'!$H$2:$H$251,MATCH(ROWS($A$27:$A29),'Raw Data'!$U$2:$U$251,0)),"") -> 5 | G29: =IFERROR(INDEX('Raw Data'!$N$2:$N$251,MATCH(ROWS($A$27:$A29),'Raw Data'!$U$2:$U$251,0)),"") -> 1499.95
A30: =IFERROR(INDEX('Raw Data'!$A$2:$A$251,MATCH(ROWS($A$27:$A30),'Raw Data'!$U$2:$U$251,0)),"") -> TRX0248 | B30: =IFERROR(INDEX('Raw Data'!$B$2:$B$251,MATCH(ROWS($A$27:$A30),'Raw Data'!$U$2:$U$251,0)),"") -> 45534 | C30: =IFERROR(INDEX('Raw Data'!$D$2:$D$251,MATCH(ROWS($A$27:$A30),'Raw Data'!$U$2:$U$251,0)),"") -> Sandra Phillips | D30: =IFERROR(INDEX('Raw Data'!$F$2:$F$251,MATCH(ROWS($A$27:$A30),'Raw Data'!$U$2:$U$251,0)),"") -> Smartphone | E30: =IFERROR(INDEX('Raw Data'!$K$2:$K$251,MATCH(ROWS($A$27:$A30),'Raw Data'!$U$2:$U$251,0)),"") -> North | F30: =IFERROR(INDEX('Raw Data'!$H$2:$H$251,MATCH(ROWS($A$27:$A30),'Raw Data'!$U$2:$U$251,0)),"") -> 2 | G30: =IFERROR(INDEX('Raw Data'!$N$2:$N$251,MATCH(ROWS($A$27:$A30),'Raw Data'!$U$2:$U$251,0)),"") -> 1399.98
A31: =IFERROR(INDEX('Raw Data'!$A$2:$A$251,MATCH(ROWS($A$27:$A31),'Raw Data'!$U$2:$U$251,0)),"") -> TRX0177 | B31: =IFERROR(INDEX('Raw Data'!$B$2:$B$251,MATCH(ROWS($A$27:$A31),'Raw Data'!$U$2:$U$251,0)),"") -> 45559 | C31: =IFERROR(INDEX('Raw Data'!$D$2:$D$251,MATCH(ROWS($A$27:$A31),'Raw Data'!$U$2:$U$251,0)),"") -> Sandra Phillips | D31: =IFERROR(INDEX('Raw Data'!$F$2:$F$251,MATCH(ROWS($A$27:$A31),'Raw Data'!$U$2:$U$251,0)),"") -> Laptop | E31: =IFERROR(INDEX('Raw Data'!$K$2:$K$251,MATCH(ROWS($A$27:$A31),'Raw Data'!$U$2:$U$251,0)),"") -> North | F31: =IFERROR(INDEX('Raw Data'!$H$2:$H$251,MATCH(ROWS($A$27:$A31),'Raw Data'!$U$2:$U$251,0)),"") -> 3 | G31: =IFERROR(INDEX('Raw Data'!$N$2:$N$251,MATCH(ROWS($A$27:$A31),'Raw Data'!$U$2:$U$251,0)),"") -> 2699.97
A32: =IFERROR(INDEX('Raw Data'!$A$2:$A$251,MATCH(ROWS($A$27:$A32),'Raw Data'!$U$2:$U$251,0)),"") -> TRX0167 | B32: =IFERROR(INDEX('Raw Data'!$B$2:$B$251,MATCH(ROWS($A$27:$A32),'Raw Data'!$U$2:$U$251,0)),"") -> 45589 | C32: =IFERROR(INDEX('Raw Data'!$D$2:$D$251,MATCH(ROWS($A$27:$A32),'Raw Data'!$U$2:$U$251,0)),"") -> Betty Campbell | D32: =IFERROR(INDEX('Raw Data'!$F$2:$F$251,MATCH(ROWS($A$27:$A32),'Raw Data'!$U$2:$U$251,0)),"") -> Smartphone | E32: =IFERROR(INDEX('Raw Data'!$K$2:$K$251,MATCH(ROWS($A$27:$A32),'Raw Data'!$U$2:$U$251,0)),"") -> North | F32: =IFERROR(INDEX('Raw Data'!$H$2:$H$251,MATCH(ROWS($A$27:$A32),'Raw Data'!$U$2:$U$251,0)),"") -> 5 | G32: =IFERROR(INDEX('Raw Data'!$N$2:$N$251,MATCH(ROWS($A$27:$A32),'Raw Data'!$U$2:$U$251,0)),"") -> 3499.95
A33: =IFERROR(INDEX('Raw Data'!$A$2:$A$251,MATCH(ROWS($A$27:$A33),'Raw Data'!$U$2:$U$251,0)),"") -> TRX0012 | B33: =IFERROR(INDEX('Raw Data'!$B$2:$B$251,MATCH(ROWS($A$27:$A33),'Raw Data'!$U$2:$U$251,0)),"") -> 45622 | C33: =IFERROR(INDEX('Raw Data'!$D$2:$D$251,MATCH(ROWS($A$27:$A33),'Raw Data'!$U$2:$U$251,0)),"") -> Douglas Watson | D33: =IFERROR(INDEX('Raw Data'!$F$2:$F$251,MATCH(ROWS($A$27:$A33),'Raw Data'!$U$2:$U$251,0)),"") -> Monitor | E33: =IFERROR(INDEX('Raw Data'!$K$2:$K$251,MATCH(ROWS($A$27:$A33),'Raw Data'!$U$2:$U$251,0)),"") -> North | F33: =IFERROR(INDEX('Raw Data'!$H$2:$H$251,MATCH(ROWS($A$27:$A33),'Raw Data'!$U$2:$U$251,0)),"") -> 5 | G33: =IFERROR(INDEX('Raw Data'!$N$2:$N$251,MATCH(ROWS($A$27:$A33),'Raw Data'!$U$2:$U$251,0)),"") -> 1249.95
A34: =IFERROR(INDEX('Raw Data'!$A$2:$A$251,MATCH(ROWS($A$27:$A34),'Raw Data'!$U$2:$U$251,0)),"") -> TRX0066 | B34: =IFERROR(INDEX('Raw Data'!$B$2:$B$251,MATCH(ROWS($A$27:$A34),'Raw Data'!$U$2:$U$251,0)),"") -> 45630 | C34: =IFERROR(INDEX('Raw Data'!$D$2:$D$251,MATCH(ROWS($A$27:$A34),'Raw Data'!$U$2:$U$251,0)),"") -> Dorothy Nelson | D34: =IFERROR(INDEX('Raw Data'!$F$2:$F$251,MATCH(ROWS($A$27:$A34),'Raw Data'!$U$2:$U$251,0)),"") -> Smartphone | E34: =IFERROR(INDEX('Raw Data'!$K$2:$K$251,MATCH(ROWS($A$27:$A34),'Raw Data'!$U$2:$U$251,0)),"") -> North | F34: =IFERROR(INDEX('Raw Data'!$H$2:$H$251,MATCH(ROWS($A$27:$A34),'Raw Data'!$U$2:$U$251,0)),"") -> 4 | G34: =IFERROR(INDEX('Raw Data'!$N$2:$N$251,MATCH(ROWS($A$27:$A34),'Raw Data'!$U$2:$U$251,0)),"") -> 2799.96
A35: =IFERROR(INDEX('Raw Data'!$A$2:$A$251,MATCH(ROWS($A$27:$A35),'Raw Data'!$U$2:$U$251,0)),"") -> TRX0032 | B35: =IFERROR(INDEX('Raw Data'!$B$2:$B$251,MATCH(ROWS($A$27:$A35),'Raw Data'!$U$2:$U$251,0)),"") -> 45638 | C35: =IFERROR(INDEX('Raw Data'!$D$2:$D$251,MATCH(ROWS($A$27:$A35),'Raw Data'!$U$2:$U$251,0)),"") -> Peter Richardson | D35: =IFERROR(INDEX('Raw Data'!$F$2:$F$251,MATCH(ROWS($A$27:$A35),'Raw Data'!$U$2:$U$251,0)),"") -> Laptop | E35: =IFERROR(INDEX('Raw Data'!$K$2:$K$251,MATCH(ROWS($A$27:$A35),'Raw Data'!$U$2:$U$251,0)),"") -> North | F35: =IFERROR(INDEX('Raw Data'!$H$2:$H$251,MATCH(ROWS($A$27:$A35),'Raw Data'!$U$2:$U$251,0)),"") -> 2 | G35: =IFERROR(INDEX('Raw Data'!$N$2:$N$251,MATCH(ROWS($A$27:$A35),'Raw Data'!$U$2:$U$251,0)),"") -> 1799.98
A36: =IFERROR(INDEX('Raw Data'!$A$2:$A$251,MATCH(ROWS($A$27:$A36),'Raw Data'!$U$2:$U$251,0)),"") -> TRX0238 | B36: =IFERROR(INDEX('Raw Data'!$B$2:$B$251,MATCH(ROWS($A$27:$A36),'Raw Data'!$U$2:$U$251,0)),"") -> 45668 | C36: =IFERROR(INDEX('Raw Data'!$D$2:$D$251,MATCH(ROWS($A$27:$A36),'Raw Data'!$U$2:$U$251,0)),"") -> Michelle Rogers | D36: =IFERROR(INDEX('Raw Data'!$F$2:$F$251,MATCH(ROWS($A$27:$A36),'Raw Data'!$U$2:$U$251,0)),"") -> Smartphone | E36: =IFERROR(INDEX('Raw Data'!$K$2:$K$251,MATCH(ROWS($A$27:$A36),'Raw Data'!$U$2:$U$251,0)),"") -> North | F36: =IFERROR(INDEX('Raw Data'!$H$2:$H$251,MATCH(ROWS($A$27:$A36),'Raw Data'!$U$2:$U$251,0)),"") -> 3 | G36: =IFERROR(INDEX('Raw Data'!$N$2:$N$251,MATCH(ROWS($A$27:$A36),'Raw Data'!$U$2:$U$251,0)),"") -> 2099.97
A37: =IFERROR(INDEX('Raw Data'!$A$2:$A$251,MATCH(ROWS($A$27:$A37),'Raw Data'!$U$2:$U$251,0)),"") -> TRX0013 | B37: =IFERROR(INDEX('Raw Data'!$B$2:$B$251,MATCH(ROWS($A$27:$A37),'Raw Data'!$U$2:$U$251,0)),"") -> 45737 | C37: =IFERROR(INDEX('Raw Data'!$D$2:$D$251,MATCH(ROWS($A$27:$A37),'Raw Data'!$U$2:$U$251,0)),"") -> Dorothy Nelson | D37: =IFERROR(INDEX('Raw Data'!$F$2:$F$251,MATCH(ROWS($A$27:$A37),'Raw Data'!$U$2:$U$251,0)),"") -> Laptop | E37: =IFERROR(INDEX('Raw Data'!$K$2:$K$251,MATCH(ROWS($A$27:$A37),'Raw Data'!$U$2:$U$251,0)),"") -> North | F37: =IFERROR(INDEX('Raw Data'!$H$2:$H$251,MATCH(ROWS($A$27:$A37),'Raw Data'!$U$2:$U$251,0)),"") -> 3 | G37: =IFERROR(INDEX('Raw Data'!$N$2:$N$251,MATCH(ROWS($A$27:$A37),'Raw Data'!$U$2:$U$251,0)),"") -> 2699.97
A38: =IFERROR(INDEX('Raw Data'!$A$2:$A$251,MATCH(ROWS($A$27:$A38),'Raw Data'!$U$2:$U$251,0)),"") -> TRX0124 | B38: =IFERROR(INDEX('Raw Data'!$B$2:$B$251,MATCH(ROWS($A$27:$A38),'Raw Data'!$U$2:$U$251,0)),"") -> 45737 | C38: =IFERROR(INDEX('Raw Data'!$D$2:$D$251,MATCH(ROWS($A$27:$A38),'Raw Data'!$U$2:$U$251,0)),"") -> Sharon Butler | D38: =IFERROR(INDEX('Raw Data'!$F$2:$F$251,MATCH(ROWS($A$27:$A38),'Raw Data'!$U$2:$U$251,0)),"") -> Laptop | E38: =IFERROR(INDEX('Raw Data'!$K$2:$K$251,MATCH(ROWS($A$27:$A38),'Raw Data'!$U$2:$U$251,0)),"") -> North | F38: =IFERROR(INDEX('Raw Data'!$H$2:$H$251,MATCH(ROWS($A$27:$A38),'Raw Data'!$U$2:$U$251,0)),"") -> 3 | G38: =IFERROR(INDEX('Raw Data'!$N$2:$N$251,MATCH(ROWS($A$27:$A38),'Raw Data'!$U$2:$U$251,0)),"") -> 2699.97
... A51: =IFERROR(INDEX('Raw Data'!$A$2:$A$251,MATCH(ROWS($A$27:$A51),'Raw Data'!$U$2:$U$251,0)),"") | B51: =IFERROR(INDEX('Raw Data'!$B$2:$B$251,MATCH(ROWS($A$27:$A51),'Raw Data'!$U$2:$U$251,0)),"") | C51: =IFERROR(INDEX('Raw Data'!$D$2:$D$251,MATCH(ROWS($A$27:$A51),'Raw Data'!$U$2:$U$251,0)),"") | D51: =IFERROR(INDEX('Raw Data'!$F$2:$F$251,MATCH(ROWS($A$27:$A51),'Raw Data'!$U$2:$U$251,0)),"") | E51: =IFERROR(INDEX('Raw Data'!$K$2:$K$251,MATCH(ROWS($A$27:$A51),'Raw Data'!$U$2:$U$251,0)),"") | F51: =IFERROR(INDEX('Raw Data'!$H$2:$H$251,MATCH(ROWS($A$27:$A51),'Raw Data'!$U$2:$U$251,0)),"") | G51: =IFERROR(INDEX('Raw Data'!$N$2:$N$251,MATCH(ROWS($A$27:$A51),'Raw Data'!$U$2:$U$251,0)),"")
A54: 3. Create Timestamp – NOW() with iterative calculation (circular reference)
A55: Type anything in column B (e.g., "Done"). Column C records the moment of entry and then stays frozen.
A58: Task / Entry | B58: Status (type here) | C58: Timestamp
A59: Entry 1 | B59: Done | C59: 46324.375
A60: Entry 2 | B60: Done | C60: 46324.375
A61: Entry 3 | B61: Done | C61: 46324.375
A62: Entry 4 | C62: =IF(B62<>"",IF(C62="",NOW(),C62),"")
...

Sheet What-If
A1: What-If Analysis – Scenario Manager & Goal Seek
A3: A. Base inputs
A4: Base Revenue (from dataset) | B4: =SUM('Raw Data'!$N$2:$N$251) -> 229192.47
A5: Cost as % of revenue (ASSUMPTION – not in dataset) | B5: 0.7
A6: Selected scenario (1=Base, 2=Best, 3=Worst) | B6: 1
A8: B. Scenario inputs (changing cells)
A9: Parameter | B9: Base | C9: Best | D9: Worst | E9: Selected
A10: Price change % | B10: 0 | C10: 0.05 | D10: -0.03 | E10: =CHOOSE($B$6,B10,C10,D10) -> 0
A11: Volume change % | B11: 0 | C11: 0.1 | D11: -0.1 | E11: =CHOOSE($B$6,B11,C11,D11) -> 0
A12: Discount % | B12: 0 | C12: 0.02 | D12: 0.08 | E12: =CHOOSE($B$6,B12,C12,D12) -> 0
A14: C. Scenario Summary (result cells)
A15: Metric | B15: Base | C15: Best | D15: Worst | E15: Selected
A16: Projected Revenue | B16: =$B$4*(1+B10)*(1+B11)*(1-B12) -> 229192.47 | C16: =$B$4*(1+C10)*(1+C11)*(1-C12) -> 259422.96 | D16: =$B$4*(1+D10)*(1+D11)*(1-D12) -> 184078.22 | E16: =$B$4*(1+E10)*(1+E11)*(1-E12) -> 229192.47
A17: Projected Cost | B17: =$B$4*(1+B11)*$B$5 -> 160434.73 | C17: =$B$4*(1+C11)*$B$5 -> 176478.2 | D17: =$B$4*(1+D11)*$B$5 -> 144391.26 | E17: =$B$4*(1+E11)*$B$5 -> 160434.73
A18: Profit | B18: =B16-B17 -> 68757.741 | C18: =C16-C17 -> 82944.755 | D18: =D16-D17 -> 39686.968 | E18: =E16-E17 -> 68757.741
A19: Profit Margin | B19: =IFERROR(B18/B16,0) -> 0.3 | C19: =IFERROR(C18/C16,0) -> 0.31972789 | D19: =IFERROR(D18/D16,0) -> 0.21559839 | E19: =IFERROR(E18/E16,0) -> 0.3
A20: Revenue vs Base % | B20: =B16/$B$16-1 -> 0 | C20: =C16/$B$16-1 -> 0.1319 | D20: =D16/$B$16-1 -> -0.19684 | E20: =E16/$B$16-1 -> 0
A21: Profit vs Base % | B21: =IFERROR(B18/$B$18-1,0) -> 0 | C21: =IFERROR(C18/$B$18-1,0) -> 0.20633333 | D21: =IFERROR(D18/$B$18-1,0) -> -0.4228 | E21: =IFERROR(E18/$B$18-1,0) -> 0
A23: D. Goal Seek – find the volume change needed to reach a revenue target
A24: Target revenue growth over base | B24: 0.15
A25: Target revenue | B25: =B4*(1+B24) -> 263571.34
A26: Price change % (fixed) | B26: 0.05
A27: Discount % (fixed) | B27: 0.02
A28: Volume change % ← CHANGING CELL | B28: 0.11758989
A29: Revenue at that volume ← SET CELL | B29: =B4*(1+B26)*(1+B28)*(1-B27) -> 263571.34
A30: Gap vs target (should be 0 after Goal Seek) | B30: =B29-B25 -> 0
A31: Check: analytical answer for B28 | B31: =B25/(B4*(1+B26)*(1-B27))-1 -> 0.11758989

Sheet Regression
A1: Linear Regression – Data Analysis ToolPak style output
A4: SUMMARY OUTPUT – Regression Statistics
A6: Multiple R | B6: =SQRT(B7) -> 0.92884475
A7: R Square | B7: =INDEX(LINEST('Raw Data'!$N$2:$N$251,'Raw Data'!$H$2:$I$251,TRUE,TRUE),3,1) -> 0.86275258
A8: Adjusted R Square | B8: =1-(1-B7)*(B10-1)/(B10-3) -> 0.86164126
A9: Standard Error | B9: =INDEX(LINEST('Raw Data'!$N$2:$N$251,'Raw Data'!$H$2:$I$251,TRUE,TRUE),3,2) -> 384.0375
A10: Observations | B10: =COUNT('Raw Data'!$N$2:$N$251) -> 250
A12: ANOVA
B13: df | C13: SS | D13: MS | E13: F | F13: Significance F
A14: Regression | B14: 2 | C14: =INDEX(LINEST('Raw Data'!$N$2:$N$251,'Raw Data'!$H$2:$I$251,TRUE,TRUE),5,1) -> 2.2899515e+08 | D14: =C14/B14 -> 1.1449757e+08 | E14: =INDEX(LINEST('Raw Data'!$N$2:$N$251,'Raw Data'!$H$2:$I$251,TRUE,TRUE),4,1) -> 776.33474 | F14: =FDIST(E14,B14,B15) -> 3.032279e-107
A15: Residual | B15: =INDEX(LINEST('Raw Data'!$N$2:$N$251,'Raw Data'!$H$2:$I$251,TRUE,TRUE),4,2) -> 247 | C15: =INDEX(LINEST('Raw Data'!$N$2:$N$251,'Raw Data'!$H$2:$I$251,TRUE,TRUE),5,2) -> 36428746 | D15: =C15/B15 -> 147484.8
A16: Total | B16: =B14+B15 -> 249 | C16: =C14+C15 -> 2.6542389e+08
A18: Coefficients
B19: Coefficients | C19: Standard Error | D19: t Stat | E19: P-value | F19: Lower 95% | G19: Upper 95%
A20: Intercept | B20: =INDEX(LINEST('Raw Data'!$N$2:$N$251,'Raw Data'!$H$2:$I$251,TRUE,TRUE),1,3) -> -931.80859 | C20: =INDEX(LINEST('Raw Data'!$N$2:$N$251,'Raw Data'!$H$2:$I$251,TRUE,TRUE),2,3) -> 64.176586 | D20: =B20/C20 -> -14.519448 | E20: =TDIST(ABS(D20),$B$15,2) -> 5.9491879e-35 | F20: =B20-TINV(0.05,$B$15)*C20 -> -1058.2117 | G20: =B20+TINV(0.05,$B$15)*C20 -> -805.40543
A21: Quantity | B21: =INDEX(LINEST('Raw Data'!$N$2:$N$251,'Raw Data'!$H$2:$I$251,TRUE,TRUE),1,2) -> 314.14588 | C21: =INDEX(LINEST('Raw Data'!$N$2:$N$251,'Raw Data'!$H$2:$I$251,TRUE,TRUE),2,2) -> 18.242562 | D21: =B21/C21 -> 17.220491 | E21: =TDIST(ABS(D21),$B$15,2) -> 3.4020508e-44 | F21: =B21-TINV(0.05,$B$15)*C21 -> 278.21506 | G21: =B21+TINV(0.05,$B$15)*C21 -> 350.0767
A22: Unit_Price | B22: =INDEX(LINEST('Raw Data'!$N$2:$N$251,'Raw Data'!$H$2:$I$251,TRUE,TRUE),1,1) -> 3.041666 | C22: =INDEX(LINEST('Raw Data'!$N$2:$N$251,'Raw Data'!$H$2:$I$251,TRUE,TRUE),2,1) -> 0.088733343 | D22: =B22/C22 -> 34.278727 | E22: =TDIST(ABS(D22),$B$15,2) -> 7.2446245e-96 | F22: =B22-TINV(0.05,$B$15)*C22 -> 2.8668955 | G22: =B22+TINV(0.05,$B$15)*C22 -> 3.2164365
A24: Prediction using the fitted equation
A25: Quantity (input) | B25: 3
A26: Unit_Price (input) | B26: 249.99
A27: Predicted Total_Amount | B27: =B20+B21*B25+B22*B26 -> 771.01516
A28: Actual Quantity × Price | B28: =B25*B26 -> 749.97

Sheet Visualizations
A1: Visualizations – Charts (linked to Analysis & Customer Analysis)

Sheet Dashboard
A1: DATA INTELLIGENCE DASHBOARD
A4: Total Revenue | C4: Transactions | E4: Units Sold | G4: Avg Order Value | I4: Unique Customers
A5: =Analysis!B4 -> 229192.47 | C5: =Analysis!B5 -> 250 | E5: =Analysis!B6 -> 753 | G5: =Analysis!B7 -> 916.76988 | I5: =Analysis!B8 -> 50
A7: KPI Indicators (last complete month vs previous month) | G7: Top 5 Customers
A8: Metric | B8: =Analysis!F54 -> Mar-25 | C8: =Analysis!F53 -> Feb-25 | D8: Change % | G8: Rank | H8: Customer | I8: Revenue | J8: Tier
A9: Revenue | B9: =Analysis!B54 -> 19899.38 | C9: =Analysis!B53 -> 16069.38 | D9: =B9/C9-1 -> 0.23834149 | G9: 1 | H9: ='Customer Analysis'!B63 -> Mark Carter | I9: ='Customer Analysis'!C63 -> 15659.65 | J9: ='Customer Analysis'!E63 -> High-Value
A10: Orders | B10: =Analysis!C54 -> 19 | C10: =Analysis!C53 -> 20 | D10: =B10/C10-1 -> -0.05 | G10: 2 | H10: ='Customer Analysis'!B64 -> Edward Mitchell | I10: ='Customer Analysis'!C64 -> 11919.77 | J10: ='Customer Analysis'!E64 -> High-Value
A11: Units | B11: =Analysis!D54 -> 62 | C11: =Analysis!D53 -> 62 | D11: =B11/C11-1 -> 0 | G11: 3 | H11: ='Customer Analysis'!B65 -> Barbara Young | I11: ='Customer Analysis'!C65 -> 10649.8 | J11: ='Customer Analysis'!E65 -> High-Value
A12: Avg Order Value | B12: =Analysis!B54/Analysis!C54 -> 1047.3358 | C12: =Analysis!B53/Analysis!C53 -> 803.469 | D12: =B12/C12-1 -> 0.30351736 | G12: 4 | H12: ='Customer Analysis'!B66 -> Patricia Moore | I12: ='Customer Analysis'!C66 -> 9799.73 | J12: ='Customer Analysis'!E66 -> High-Value
G13: 5 | H13: ='Customer Analysis'!B67 -> Paul Baker | I13: ='Customer Analysis'!C67 -> 8309.74 | J13: ='Customer Analysis'!E67 -> High-Value
A14: Regional Sales (pivot-style) | G14: Top 5 Most Sold Products
A15: Region | B15: Revenue | C15: % Share | D15: Index vs Avg | G15: Rank | H15: Product (most sold) | I15: Units | J15: Revenue
A16: =Analysis!A13 -> Central | B16: =Analysis!B13 -> 41288.34 | C16: =Analysis!E13 -> 0.18014702 | D16: =Analysis!G13 -> 0.90073509 | G16: 1 | H16: =Analysis!B84 -> Bookshelf | I16: =Analysis!C84 -> 102 | J16: =Analysis!D84 -> 15298.98
A17: =Analysis!A14 -> East | B17: =Analysis!B14 -> 59288.39 | C17: =Analysis!E14 -> 0.25868385 | D17: =Analysis!G14 -> 1.2934192 | G17: 2 | H17: =Analysis!B85 -> Smartphone | I17: =Analysis!C85 -> 96 | J17: =Analysis!D85 -> 67199.04
A18: =Analysis!A15 -> North | B18: =Analysis!B15 -> 50808.31 | C18: =Analysis!E15 -> 0.22168403 | D18: =Analysis!G15 -> 1.1084201 | G18: 3 | H18: =Analysis!B86 -> Keyboard | I18: =Analysis!C86 -> 89 | J18: =Analysis!D86 -> 8009.11
A19: =Analysis!A16 -> South | B19: =Analysis!B16 -> 36398.75 | C19: =Analysis!E16 -> 0.15881303 | D19: =Analysis!G16 -> 0.79406514 | G19: 4 | H19: =Analysis!B87 -> Monitor | I19: =Analysis!C87 -> 88 | J19: =Analysis!D87 -> 21999.12
A20: =Analysis!A17 -> West | B20: =Analysis!B17 -> 41408.68 | C20: =Analysis!E17 -> 0.18067208 | D20: =Analysis!G17 -> 0.90336039 | G20: 5 | H20: =Analysis!B88 -> Blender | I20: =Analysis!C88 -> 87 | J20: =Analysis!D88 -> 5219.13

Sheet Report
A1: Final Report – Insights & Storytelling
A3: A. Summary Insights – key metrics
A4: Total Revenue | B4: =Analysis!B4 -> 229192.47
A5: Total Transactions | B5: =Analysis!B5 -> 250
A6: Average Order Value | B6: =Analysis!B7 -> 916.76988
A8: Top Customers | B8: Revenue | C8: % of Revenue | E8: Most Sold Products | F8: Units | G8: Revenue
A9: ='Customer Analysis'!B63 -> Mark Carter | B9: ='Customer Analysis'!C63 -> 15659.65 | C9: ='Customer Analysis'!F63 -> 0.068325325 | E9: =Analysis!B84 -> Bookshelf | F9: =Analysis!C84 -> 102 | G9: =Analysis!D84 -> 15298.98
A10: ='Customer Analysis'!B64 -> Edward Mitchell | B10: ='Customer Analysis'!C64 -> 11919.77 | C10: ='Customer Analysis'!F64 -> 0.052007686 | E10: =Analysis!B85 -> Smartphone | F10: =Analysis!C85 -> 96 | G10: =Analysis!D85 -> 67199.04
A11: ='Customer Analysis'!B65 -> Barbara Young | B11: ='Customer Analysis'!C65 -> 10649.8 | C11: ='Customer Analysis'!F65 -> 0.046466623 | E11: =Analysis!B86 -> Keyboard | F11: =Analysis!C86 -> 89 | G11: =Analysis!D86 -> 8009.11
A12: ='Customer Analysis'!B66 -> Patricia Moore | B12: ='Customer Analysis'!C66 -> 9799.73 | C12: ='Customer Analysis'!F66 -> 0.042757644 | E12: =Analysis!B87 -> Monitor | F12: =Analysis!C87 -> 88 | G12: =Analysis!D87 -> 21999.12
A13: ='Customer Analysis'!B67 -> Paul Baker | B13: ='Customer Analysis'!C67 -> 8309.74 | C13: ='Customer Analysis'!F67 -> 0.036256601 | E13: =Analysis!B88 -> Blender | F13: =Analysis!C88 -> 87 | G13: =Analysis!D88 -> 5219.13
A16: Regional Sales | B16: Revenue | C16: % Share
A17: =Analysis!A13 -> Central | B17: =Analysis!B13 -> 41288.34 | C17: =Analysis!E13 -> 0.18014702
A18: =Analysis!A14 -> East | B18: =Analysis!B14 -> 59288.39 | C18: =Analysis!E14 -> 0.25868385
A19: =Analysis!A15 -> North | B19: =Analysis!B15 -> 50808.31 | C19: =Analysis!E15 -> 0.22168403
A20: =Analysis!A16 -> South | B20: =Analysis!B16 -> 36398.75 | C20: =Analysis!E16 -> 0.15881303
A21: =Analysis!A17 -> West | B21: =Analysis!B17 -> 41408.68 | C21: =Analysis!E17 -> 0.18067208
A23: B. The Story – what the data tells us
A24: 1. Overview | B24: ="Between "&TEXT(DateTime_Filter!B7,"dd-mmm-yyyy")&" and "&TEXT(DateTime_Filter!B8,"dd-mmm-yyyy")&", the business recorded "&TEXT(Analysis!B5,"#,##0")&" transactions worth "&TEXT(Analysis!B4,"$#,##0")&" from "&Analysis!B8&" customers, with an average order value of "&TEXT(Analysis!B7,"$#,##0")&"." -> Between 11-Apr-2024 and 11-Apr-2025, the business recorded 250 transactions worth $2,29,192 from 50 customers, with an average order value of $917.
